Workbook

Sheet Overview
B2: BS Mechanical Engineering
B3: Total Credits Completed so Far | C3: Remaining Credits | D3: %Complete
B4: =SUMIF('BS Mechanical Engineering'!E5:E33,TRUE,'BS Mechanical Engineering'!G5:G33)+SUMIF('BS Mechanical Engineering'!E37:E42,TRUE,'BS Mechanical Engineering'!G37:G42)+SUMIF('BS Mechanical Engineering'!L5:L10,TRUE,'BS Mechanical Engineering'!N5:N10)+IF('BS Mechanical Engineering'!L16=TRUE,'BS Mechanical Engineering'!N16,0) -> 0 | C4: =SUMIF('BS Mechanical Engineering'!E5:E33,FALSE,'BS Mechanical Engineering'!G5:G33)+SUMIF('BS Mechanical Engineering'!E37:E42,FALSE,'BS Mechanical Engineering'!G37:G42)+SUMIF('BS Mechanical Engineering'!L5:L10,FALSE,'BS Mechanical Engineering'!N5:N10)+'BS Mechanical Engineering'!N16 -> 125 | D4: =(B4/(C4+B4))*99+IF('BS Mechanical Engineering'!J13=TRUE,0.5,0)+IF('BS Mechanical Engineering'!K13=TRUE,0.5,0) -> 0.5
B7: Overall
B8: Total Credits Completed | C8: GPA | D8: Academic Level for Enrollment
B9: =B4+F4+#REF! -> #REF! | C9: ='GPA Calculations'!C3 -> #DIV/0! | D9: =VLOOKUP(Overview!B9,'GPA Calculations'!$I$5:'GPA Calculations'!$J$8,2) -> #REF!

Sheet BS Mechanical Engineering
C2: Note: put N/A for classes that don’t affect GPA | E2: Current Term: | F2: 1
B4: Term | C4: Required Classes | D4: Name | E4: Complete? | F4: Grade | G4: Credits | I4: Term | J4: Humanites/Social Science elective requirements | K4: Name | L4: Complete? | M4: Grade | N4: Credits
B5: 1 | C5: CHEM 0110 | D5: Chemistry 1 | E5: FALSE | F5: {=_xlfn.IFS(B5=F$2,"IP",E5=FALSE," ",E5=TRUE,"Missing Grade")} -> IP | G5: 3 | I5: 1 | J5: ENGCMP 0210 | K5: Technical Writing for Engineers | L5: FALSE | M5: {=_xlfn.IFS(I5=F$2,"IP",L5=FALSE," ",L5=TRUE,"Missing Grade")} -> IP | N5: 3
B6: AP Credit | C6: MATH 0220 | D6: Calculus 1 | E6: FALSE | F6: {=_xlfn.IFS(B6=F$2,"IP",E6=FALSE," ",E6=TRUE,"Missing Grade")} | G6: 4 | I6: 2 | J6: ENGCMP 0412 | K6: Technical Writing for Engineers | L6: FALSE | M6: {=_xlfn.IFS(I6=F$2,"IP",L6=FALSE," ",L6=TRUE,"Missing Grade")} | N6: 3 | S6: =M10
B7: 1 | C7: PHYS 0174 | D7: Physics 1 | E7: FALSE | F7: {=_xlfn.IFS(B7=F$2,"IP",E7=FALSE," ",E7=TRUE,"Missing Grade")} -> IP | G7: 4 | L7: FALSE | M7: {=_xlfn.IFS(I7=F$2,"IP",L7=FALSE," ",L7=TRUE,"Missing Grade")} | N7: 3
B8: 1 | C8: ENGR 0011 | D8: Intro to Engineering Analysis | E8: FALSE | F8: {=_xlfn.IFS(B8=F$2,"IP",E8=FALSE," ",E8=TRUE,"Missing Grade")} -> IP | G8: 3 | L8: FALSE | M8: {=_xlfn.IFS(I8=F$2,"IP",L8=FALSE," ",L8=TRUE,"Missing Grade")} | N8: 3
B9: 1 | C9: ENGR 0081 | D9: Freshman Seminar 1 | E9: FALSE | F9: {=_xlfn.IFS(B9=F$2,"IP",E9=FALSE," ",E9=TRUE,"Missing Grade")} -> IP | G9: 0 | L9: FALSE | M9: {=_xlfn.IFS(I9=F$2,"IP",L9=FALSE," ",L9=TRUE,"Missing Grade")} | N9: 3
B10: 2 | C10: CHEM 0120 | D10: Chemistry 2 | E10: FALSE | F10: {=_xlfn.IFS(B10=F$2,"IP",E10=FALSE," ",E10=TRUE,"Missing Grade")} | G10: 3 | L10: FALSE | M10: {=_xlfn.IFS(I10=F$2,"IP",L10=FALSE," ",L10=TRUE,"Missing Grade")} | N10: 3
B11: 1 | C11: MATH 0230 | D11: Calculus 2 | E11: FALSE | F11: {=_xlfn.IFS(B11=F$2,"IP",E11=FALSE," ",E11=TRUE,"Missing Grade")} -> IP | G11: 4
B12: 2 | C12: PHYS 0175 | D12: Physics 2 | E12: FALSE | F12: {=_xlfn.IFS(B12=F$2,"IP",E12=FALSE," ",E12=TRUE,"Missing Grade")} | G12: 4 | J12: Breadth Requirement? | K12: Depth Requirement?
B13: 2 | C13: ENGR 0012 | D13: Engineering Analysis and Computing | E13: FALSE | F13: {=_xlfn.IFS(B13=F$2,"IP",E13=FALSE," ",E13=TRUE,"Missing Grade")} | G13: 3 | J13: FALSE | K13: TRUE
B14: 2 | C14: ENGR 0082 | D14: Freshman Seminar 2 | E14: FALSE | F14: {=_xlfn.IFS(B14=F$2,"IP",E14=FALSE," ",E14=TRUE,"Missing Grade")} | G14: 0
B15: 2 | C15: MATH 0240 | D15: Calculus 3 | E15: FALSE | F15: {=_xlfn.IFS(B15=F$2,"IP",E15=FALSE," ",E15=TRUE,"Missing Grade")} | G15: 4 | I15: Term | J15: Other | K15: Name | L15: Complete? | M15: Grade | N15: Credits
B16: 2 | C16: MATH 0280 | D16: Linear Algebra | E16: FALSE | F16: {=_xlfn.IFS(B16=F$2,"IP",E16=FALSE," ",E16=TRUE,"Missing Grade")} | G16: 3 | J16: Open Elective | L16: FALSE | M16: {=_xlfn.IFS(I16=F$2,"IP",L16=FALSE," ",L5=TRUE,"Missing Grade")} | N16: 3
B17: 3 | C17: ENGR 0022 | D17: Mater. Struct. & Properties | E17: FALSE | F17: {=_xlfn.IFS(B17=F$2,"IP",E17=FALSE," ",E17=TRUE,"Missing Grade")} | G17: 3 | L17: FALSE | M17: {=_xlfn.IFS(I17=F$2,"IP",L17=FALSE," ",L6=TRUE,"Missing Grade")}
B18: 3 | C18: ENGR 0135 | D18: Statics 1 | E18: FALSE | F18: {=_xlfn.IFS(B18=F$2,"IP",E18=FALSE," ",E18=TRUE,"Missing Grade")} | G18: 3 | L18: FALSE | M18: {=_xlfn.IFS(I18=F$2,"IP",L18=FALSE," ",L7=TRUE,"Missing Grade")}
B19: 3 | C19: MEMS 0024 | D19: Intro to ME Design | E19: FALSE | F19: {=_xlfn.IFS(B19=F$2,"IP",E19=FALSE," ",E19=TRUE,"Missing Grade")} | G19: 3
B20: 3 | C20: MATH 0290 | D20: Differential Equations | E20: FALSE | F20: {=_xlfn.IFS(B20=F$2,"IP",E20=FALSE," ",E20=TRUE,"Missing Grade")} | G20: 3
B21: Any | C21: ENGR 0145 | D21: Statics 2 | E21: FALSE | F21: {=_xlfn.IFS(B21=F$2,"IP",E21=FALSE," ",E21=TRUE,"Missing Grade")} | G21: 3
B22: Spring, Summer | C22: MEMS 0031 | D22: Electrical Circuts | E22: FALSE | F22: {=_xlfn.IFS(B22=F$2,"IP",E22=FALSE," ",E22=TRUE,"Missing Grade")} | G22: 3
B23: Spring, Summer | C23: MEMS 0051 | D23: Intro to Thermodynamics | E23: FALSE | F23: {=_xlfn.IFS(B23=F$2,"IP",E23=FALSE," ",E23=TRUE,"Missing Grade")} | G23: 3
B24: Spring, Summer | C24: MEMS 1015 | D24: Rigid-Body Dynamics | E24: FALSE | F24: {=_xlfn.IFS(B24=F$2,"IP",E24=FALSE," ",E24=TRUE,"Missing Grade")} | G24: 3
B25: Fall, Spring | C25: MEMS 0071 | D25: Intro to Fluid Mechanics | E25: FALSE | F25: {=_xlfn.IFS(B25=F$2,"IP",E25=FALSE," ",E25=TRUE,"Missing Grade")} | G25: 3
B26: Fall, Spring | C26: MEMS 1014 | D26: Dynamic Systems | E26: FALSE | F26: {=_xlfn.IFS(B26=F$2,"IP",E26=FALSE," ",E26=TRUE,"Missing Grade")} | G26: 3
B27: Fall, Spring | C27: MEMS 1028 | D27: Mechanical Design 1 | E27: FALSE | F27: {=_xlfn.IFS(B27=F$2,"IP",E27=FALSE," ",E27=TRUE,"Missing Grade")} | G27: 3
B28: Spring, Summer | C28: MEMS 0040 | D28: Materials & Manufacturing | E28: FALSE | F28: {=_xlfn.IFS(B28=F$2,"IP",E28=FALSE," ",E28=TRUE,"Missing Grade")} | G28: 3
B29: Spring, Summer | C29: MEMS 1029 | D29: Mechanical Design 2 | E29: FALSE | F29: {=_xlfn.IFS(B29=F$2,"IP",E29=FALSE," ",E29=TRUE,"Missing Grade")} | G29: 3
B30: Fall, Spring | C30: MEMS 1041 | D30: Mechanical Measurements 1 | E30: FALSE | F30: {=_xlfn.IFS(B30=F$2,"IP",E30=FALSE," ",E30=TRUE,"Missing Grade")} | G30: 3
B31: Any | C31: MEMS 1042 | D31: Mechanical Measurements 2 | E31: FALSE | F31: {=_xlfn.IFS(B31=F$2,"IP",E31=FALSE," ",E31=TRUE,"Missing Grade")} | G31: 3
B32: Fall, Summer | C32: MEMS 1052 | D32: Heat and Mass Transfer | E32: FALSE | F32: {=_xlfn.IFS(B32=F$2,"IP",E32=FALSE," ",E32=TRUE,"Missing Grade")} | G32: 3
B33: Any | C33: MEMS 1043 | D33: Senior Design | E33: FALSE | F33: {=_xlfn.IFS(B33=F$2,"IP",E33=FALSE," ",E33=TRUE,"Missing Grade")} | G33: 3
B36: Term | C36: Elective | D36: Name | E36: Complete? | F36: Grade | G36: Credits
C37: Engineering Elective | E37: FALSE | F37: {=_xlfn.IFS(B37=F$2,"IP",E37=FALSE," ",E37=TRUE,"Missing Connection to Grade Calculator")} | G37: 3
C38: Dynamic Systems Elective | E38: FALSE | F38: {=_xlfn.IFS(B38=F$2,"IP",E38=FALSE," ",E38=TRUE,"Missing Connection to Grade Calculator")} | G38: 3
C39: ME Technical Elective | E39: FALSE | F39: {=_xlfn.IFS(B39=F$2,"IP",E39=FALSE," ",E39=TRUE,'[1]Semester 3'!$T$12)} | G39: 3
C40: ME Technical Elective | E40: FALSE | F40: {=_xlfn.IFS(B40=F$2,"IP",E40=FALSE," ",E40=TRUE,"Missing Connection to Grade Calculator")} | G40: 3
C41: ME Technical Elective | E41: FALSE | F41: {=_xlfn.IFS(B41=F$2,"IP",E41=FALSE," ",E41=TRUE,"Missing Connection to Grade Calculator")} | G41: 3
C42: ME Technical Elective | E42: FALSE | F42: {=_xlfn.IFS(B42=F$2,"IP",E42=FALSE," ",E42=TRUE,"Missing Connection to Grade Calculator")} | G42: 3

Sheet GPA Calculations
B2: Total Completed Classes | C2: GPA
B3: =COUNTIF(E7:E52,FALSE) -> 0 | C3: =(SUMIF(E7:E52,FALSE,(G7:G52)))/(SUMIF(E7:E52,FALSE,(D7:D52))) -> #DIV/0! | I3: Enrollment classification reference
I4: Completed credit totals | J4: Academic level for enrollment
B5: Class Data | I5: 0 | J5: Freshman
B6: Completion Status | C6: Grade | D6: Credits | E6: Completed graded classes = False | F6: GPA Value | G6: Credit-Weighted GPA | I6: 24 | J6: Sophomore
B7: ='BS Mechanical Engineering'!E5 -> FALSE | C7: ='BS Mechanical Engineering'!F5 -> IP | D7: ='BS Mechanical Engineering'!G5 -> 3 | E7: =OR(C7="N/A",C7="IP",C7=" ",C7="Missing Grade",B7=FALSE) -> TRUE | F7: =IF(E7=FALSE,(VLOOKUP(C7,I$12:J$24,2)),"N/A") -> N/A | G7: =F7*D7 -> #VALUE! | I7: 54 | J7: Junior
B8: ='BS Mechanical Engineering'!E6 -> FALSE | C8: ='BS Mechanical Engineering'!F6 | D8: ='BS Mechanical Engineering'!G6 -> 4 | E8: =OR(C8="N/A",C8="IP",C8=" ",C8="Missing Grade",B8=FALSE) -> TRUE | F8: =IF(E8=FALSE,(VLOOKUP(C8,I$12:J$24,2)),"N/A") -> N/A | G8: =F8*D8 -> #VALUE! | I8: 84 | J8: Senior
B9: ='BS Mechanical Engineering'!E7 -> FALSE | C9: ='BS Mechanical Engineering'!F7 -> IP | D9: ='BS Mechanical Engineering'!G7 -> 4 | E9: =OR(C9="N/A",C9="IP",C9=" ",C9="Missing Grade",B9=FALSE) -> TRUE | F9: =IF(E9=FALSE,(VLOOKUP(C9,I$12:J$24,2)),"N/A") -> N/A | G9: =F9*D9 -> #VALUE!
B10: ='BS Mechanical Engineering'!E8 -> FALSE | C10: ='BS Mechanical Engineering'!F8 -> IP | D10: ='BS Mechanical Engineering'!G8 -> 3 | E10: =OR(C10="N/A",C10="IP",C10=" ",C10="Missing Grade",B10=FALSE) -> TRUE | F10: =IF(E10=FALSE,(VLOOKUP(C10,I$12:J$24,2)),"N/A") -> N/A | G10: =F10*D10 -> #VALUE!
B11: ='BS Mechanical Engineering'!E9 -> FALSE | C11: ='BS Mechanical Engineering'!F9 -> IP | D11: ='BS Mechanical Engineering'!G9 -> 0 | E11: =OR(C11="N/A",C11="IP",C11=" ",C11="Missing Grade",B11=FALSE) -> TRUE | F11: =IF(E11=FALSE,(VLOOKUP(C11,I$12:J$24,2)),"N/A") -> N/A | G11: =F11*D11 -> #VALUE! | I11: GPA Reference
B12: ='BS Mechanical Engineering'!E10 -> FALSE | C12: ='BS Mechanical Engineering'!F10 | D12: ='BS Mechanical Engineering'!G10 -> 3 | E12: =OR(C12="N/A",C12="IP",C12=" ",C12="Missing Grade",B12=FALSE) -> TRUE | F12: =IF(E12=FALSE,(VLOOKUP(C12,I$12:J$24,2)),"N/A") -> N/A | G12: =F12*D12 -> #VALUE! | I12: ="A" -> A | J12: 4
B13: ='BS Mechanical Engineering'!E11 -> FALSE | C13: ='BS Mechanical Engineering'!F11 -> IP | D13: ='BS Mechanical Engineering'!G11 -> 4 | E13: =OR(C13="N/A",C13="IP",C13=" ",C13="Missing Grade",B13=FALSE) -> TRUE | F13: =IF(E13=FALSE,(VLOOKUP(C13,I$12:J$24,2)),"N/A") -> N/A | G13: =F13*D13 -> #VALUE! | I13: ="A-" -> A- | J13: 3.75
B14: ='BS Mechanical Engineering'!E12 -> FALSE | C14: ='BS Mechanical Engineering'!F12 | D14: ='BS Mechanical Engineering'!G12 -> 4 | E14: =OR(C14="N/A",C14="IP",C14=" ",C14="Missing Grade",B14=FALSE) -> TRUE | F14: =IF(E14=FALSE,(VLOOKUP(C14,I$12:J$24,2)),"N/A") -> N/A | G14: =F14*D14 -> #VALUE! | I14: ="A+" -> A+ | J14: 4
B15: ='BS Mechanical Engineering'!E13 -> FALSE | C15: ='BS Mechanical Engineering'!F13 | D15: ='BS Mechanical Engineering'!G13 -> 3 | E15: =OR(C15="N/A",C15="IP",C15=" ",C15="Missing Grade",B15=FALSE) -> TRUE | F15: =IF(E15=FALSE,(VLOOKUP(C15,I$12:J$24,2)),"N/A") -> N/A | G15: =F15*D15 -> #VALUE! | I15: ="B" -> B | J15: 3
B16: ='BS Mechanical Engineering'!E14 -> FALSE | C16: ='BS Mechanical Engineering'!F14 | D16: ='BS Mechanical Engineering'!G14 -> 0 | E16: =OR(C16="N/A",C16="IP",C16=" ",C16="Missing Grade",B16=FALSE) -> TRUE | F16: =IF(E16=FALSE,(VLOOKUP(C16,I$12:J$24,2)),"N/A") -> N/A | G16: =F16*D16 -> #VALUE! | I16: ="B-" -> B- | J16: 2.75
B17: ='BS Mechanical Engineering'!E15 -> FALSE | C17: ='BS Mechanical Engineering'!F15 | D17: ='BS Mechanical Engineering'!G15 -> 4 | E17: =OR(C17="N/A",C17="IP",C17=" ",C17="Missing Grade",B17=FALSE) -> TRUE | F17: =IF(E17=FALSE,(VLOOKUP(C17,I$12:J$24,2)),"N/A") -> N/A | G17: =F17*D17 -> #VALUE! | I17: ="B+" -> B+ | J17: 3.25
B18: ='BS Mechanical Engineering'!E16 -> FALSE | C18: ='BS Mechanical Engineering'!F16 | D18: ='BS Mechanical Engineering'!G16 -> 3 | E18: =OR(C18="N/A",C18="IP",C18=" ",C18="Missing Grade",B18=FALSE) -> TRUE | F18: =IF(E18=FALSE,(VLOOKUP(C18,I$12:J$24,2)),"N/A") -> N/A | G18: =F18*D18 -> #VALUE! | I18: ="C" -> C | J18: 2
B19: ='BS Mechanical Engineering'!E17 -> FALSE | C19: ='BS Mechanical Engineering'!F17 | D19: ='BS Mechanical Engineering'!G17 -> 3 | E19: =OR(C19="N/A",C19="IP",C19=" ",C19="Missing Grade",B19=FALSE) -> TRUE | F19: =IF(E19=FALSE,(VLOOKUP(C19,I$12:J$24,2)),"N/A") -> N/A | G19: =F19*D19 -> #VALUE! | I19: ="C-" -> C- | J19: 1.75
B20: ='BS Mechanical Engineering'!E18 -> FALSE | C20: ='BS Mechanical Engineering'!F18 | D20: ='BS Mechanical Engineering'!G18 -> 3 | E20: =OR(C20="N/A",C20="IP",C20=" ",C20="Missing Grade",B20=FALSE) -> TRUE | F20: =IF(E20=FALSE,(VLOOKUP(C20,I$12:J$24,2)),"N/A") -> N/A | G20: =F20*D20 -> #VALUE! | I20: ="C+" -> C+ | J20: 2.25
B21: ='BS Mechanical Engineering'!E19 -> FALSE | C21: ='BS Mechanical Engineering'!F19 | D21: ='BS Mechanical Engineering'!G19 -> 3 | E21: =OR(C21="N/A",C21="IP",C21=" ",C21="Missing Grade",B21=FALSE) -> TRUE | F21: =IF(E21=FALSE,(VLOOKUP(C21,I$12:J$24,2)),"N/A") -> N/A | G21: =F21*D21 -> #VALUE! | I21: ="D" -> D | J21: 1
B22: ='BS Mechanical Engineering'!E20 -> FALSE | C22: ='BS Mechanical Engineering'!F20 | D22: ='BS Mechanical Engineering'!G20 -> 3 | E22: =OR(C22="N/A",C22="IP",C22=" ",C22="Missing Grade",B22=FALSE) -> TRUE | F22: =IF(E22=FALSE,(VLOOKUP(C22,I$12:J$24,2)),"N/A") -> N/A | G22: =F22*D22 -> #VALUE! | I22: ="D-" -> D- | J22: 0.75
B23: ='BS Mechanical Engineering'!E21 -> FALSE | C23: ='BS Mechanical Engineering'!F21 | D23: ='BS Mechanical Engineering'!G21 -> 3 | E23: =OR(C23="N/A",C23="IP",C23=" ",C23="Missing Grade",B23=FALSE) -> TRUE | F23: =IF(E23=FALSE,(VLOOKUP(C23,I$12:J$24,2)),"N/A") -> N/A | G23: =F23*D23 -> #VALUE! | I23: ="D+" -> D+ | J23: 1.25
B24: ='BS Mechanical Engineering'!E22 -> FALSE | C24: ='BS Mechanical Engineering'!F22 | D24: ='BS Mechanical Engineering'!G22 -> 3 | E24: =OR(C24="N/A",C24="IP",C24=" ",C24="Missing Grade",B24=FALSE) -> TRUE | F24: =IF(E24=FALSE,(VLOOKUP(C24,I$12:J$24,2)),"N/A") -> N/A | G24: =F24*D24 -> #VALUE! | I24: ="F" -> F | J24: 0
B25: ='BS Mechanical Engineering'!E23 -> FALSE | C25: ='BS Mechanical Engineering'!F23 | D25: ='BS Mechanical Engineering'!G23 -> 3 | E25: =OR(C25="N/A",C25="IP",C25=" ",C25="Missing Grade",B25=FALSE) -> TRUE | F25: =IF(E25=FALSE,(VLOOKUP(C25,I$12:J$24,2)),"N/A") -> N/A | G25: =F25*D25 -> #VALUE!
B26: ='BS Mechanical Engineering'!E24 -> FALSE | C26: ='BS Mechanical Engineering'!F24 | D26: ='BS Mechanical Engineering'!G24 -> 3 | E26: =OR(C26="N/A",C26="IP",C26=" ",C26="Missing Grade",B26=FALSE) -> TRUE | F26: =IF(E26=FALSE,(VLOOKUP(C26,I$12:J$24,2)),"N/A") -> N/A | G26: =F26*D26 -> #VALUE!
B27: ='BS Mechanical Engineering'!E25 -> FALSE | C27: ='BS Mechanical Engineering'!F25 | D27: ='BS Mechanical Engineering'!G25 -> 3 | E27: =OR(C27="N/A",C27="IP",C27=" ",C27="Missing Grade",B27=FALSE) -> TRUE | F27: =IF(E27=FALSE,(VLOOKUP(C27,I$12:J$24,2)),"N/A") -> N/A | G27: =F27*D27 -> #VALUE!
B28: ='BS Mechanical Engineering'!E26 -> FALSE | C28: ='BS Mechanical Engineering'!F26 | D28: ='BS Mechanical Engineering'!G26 -> 3 | E28: =OR(C28="N/A",C28="IP",C28=" ",C28="Missing Grade",B28=FALSE) -> TRUE | F28: =IF(E28=FALSE,(VLOOKUP(C28,I$12:J$24,2)),"N/A") -> N/A | G28: =F28*D28 -> #VALUE!
B29: ='BS Mechanical Engineering'!E27 -> FALSE | C29: ='BS Mechanical Engineering'!F27 | D29: ='BS Mechanical Engineering'!G27 -> 3 | E29: =OR(C29="N/A",C29="IP",C29=" ",C29="Missing Grade",B29=FALSE) -> TRUE | F29: =IF(E29=FALSE,(VLOOKUP(C29,I$12:J$24,2)),"N/A") -> N/A | G29: =F29*D29 -> #VALUE!
B30: ='BS Mechanical Engineering'!E28 -> FALSE | C30: ='BS Mechanical Engineering'!F28 | D30: ='BS Mechanical Engineering'!G28 -> 3 | E30: =OR(C30="N/A",C30="IP",C30=" ",C30="Missing Grade",B30=FALSE) -> TRUE | F30: =IF(E30=FALSE,(VLOOKUP(C30,I$12:J$24,2)),"N/A") -> N/A | G30: =F30*D30 -> #VALUE!
B31: ='BS Mechanical Engineering'!E29 -> FALSE | C31: ='BS Mechanical Engineering'!F29 | D31: ='BS Mechanical Engineering'!G29 -> 3 | E31: =OR(C31="N/A",C31="IP",C31=" ",C31="Missing Grade",B31=FALSE) -> TRUE | F31: =IF(E31=FALSE,(VLOOKUP(C31,I$12:J$24,2)),"N/A") -> N/A | G31: =F31*D31 -> #VALUE!
B32: ='BS Mechanical Engineering'!E30 -> FALSE | C32: ='BS Mechanical Engineering'!F30 | D32: ='BS Mechanical Engineering'!G30 -> 3 | E32: =OR(C32="N/A",C32="IP",C32=" ",C32="Missing Grade",B32=FALSE) -> TRUE | F32: =IF(E32=FALSE,(VLOOKUP(C32,I$12:J$24,2)),"N/A") -> N/A | G32: =F32*D32 -> #VALUE!
B33: ='BS Mechanical Engineering'!E31 -> FALSE | C33: ='BS Mechanical Engineering'!F31 | D33: ='BS Mechanical Engineering'!G31 -> 3 | E33: =OR(C33="N/A",C33="IP",C33=" ",C33="Missing Grade",B33=FALSE) -> TRUE | F33: =IF(E33=FALSE,(VLOOKUP(C33,I$12:J$24,2)),"N/A") -> N/A | G33: =F33*D33 -> #VALUE!
B34: ='BS Mechanical Engineering'!E32 -> FALSE | C34: ='BS Mechanical Engineering'!F32 | D34: ='BS Mechanical Engineering'!G32 -> 3 | E34: =OR(C34="N/A",C34="IP",C34=" ",C34="Missing Grade",B34=FALSE) -> TRUE | F34: =IF(E34=FALSE,(VLOOKUP(C34,I$12:J$24,2)),"N/A") -> N/A | G34: =F34*D34 -> #VALUE!
B35: ='BS Mechanical Engineering'!E33 -> FALSE | C35: ='BS Mechanical Engineering'!F33 | D35: ='BS Mechanical Engineering'!G33 -> 3 | E35: =OR(C35="N/A",C35="IP",C35=" ",C35="Missing Grade",B35=FALSE) -> TRUE | F35: =IF(E35=FALSE,(VLOOKUP(C35,I$12:J$24,2)),"N/A") -> N/A | G35: =F35*D35 -> #VALUE!
B36: ='BS Mechanical Engineering'!E37 -> FALSE | C36: ='BS Mechanical Engineering'!F37 | D36: ='BS Mechanical Engineering'!G37 -> 3 | E36: =OR(C36="N/A",C36="IP",C36=" ",C36="Missing Grade",B36=FALSE) -> TRUE | F36: =IF(E36=FALSE,(VLOOKUP(C36,I$12:J$24,2)),"N/A") -> N/A | G36: =F36*D36 -> #VALUE!
B37: ='BS Mechanical Engineering'!E38 -> FALSE | C37: ='BS Mechanical Engineering'!F38 | D37: ='BS Mechanical Engineering'!G38 -> 3 | E37: =OR(C37="N/A",C37="IP",C37=" ",C37="Missing Grade",B37=FALSE) -> TRUE | F37: =IF(E37=FALSE,(VLOOKUP(C37,I$12:J$24,2)),"N/A") -> N/A | G37: =F37*D37 -> #VALUE!
B38: ='BS Mechanical Engineering'!E39 -> FALSE | C38: ='BS Mechanical Engineering'!F39 | D38: ='BS Mechanical Engineering'!G39 -> 3 | E38: =OR(C38="N/A",C38="IP",C38=" ",C38="Missing Grade",B38=FALSE) -> TRUE | F38: =IF(E38=FALSE,(VLOOKUP(C38,I$12:J$24,2)),"N/A") -> N/A | G38: =F38*D38 -> #VALUE!
B39: ='BS Mechanical Engineering'!E40 -> FALSE | C39: ='BS Mechanical Engineering'!F40 | D39: ='BS Mechanical Engineering'!G40 -> 3 | E39: =OR(C39="N/A",C39="IP",C39=" ",C39="Missing Grade",B39=FALSE) -> TRUE | F39: =IF(E39=FALSE,(VLOOKUP(C39,I$12:J$24,2)),"N/A") -> N/A | G39: =F39*D39 -> #VALUE!
B40: ='BS Mechanical Engineering'!E41 -> FALSE | C40: ='BS Mechanical Engineering'!F41 | D40: ='BS Mechanical Engineering'!G41 -> 3 | E40: =OR(C40="N/A",C40="IP",C40=" ",C40="Missing Grade",B40=FALSE) -> TRUE | F40: =IF(E40=FALSE,(VLOOKUP(C40,I$12:J$24,2)),"N/A") -> N/A | G40: =F40*D40 -> #VALUE!
B41: ='BS Mechanical Engineering'!E42 -> FALSE | C41: ='BS Mechanical Engineering'!F42 | D41: ='BS Mechanical Engineering'!G42 -> 3 | E41: =OR(C41="N/A",C41="IP",C41=" ",C41="Missing Grade",B41=FALSE) -> TRUE | F41: =IF(E41=FALSE,(VLOOKUP(C41,I$12:J$24,2)),"N/A") -> N/A | G41: =F41*D41 -> #VALUE!
...
