Workbook

Sheet Overview
B2: Degree Name | F2: Minor Name
B3: Total Credits Completed so Far | C3: Remaining Credits | D3: %Complete | F3: Total Credits Completed so Far | G3: Remaining Credits | H3: %Complete
B4: =SUMIF(Major!E3:E31,TRUE,Major!G3:G31)+SUMIF(Major!L3:L8,TRUE,Major!N3:N8)+SUMIF(Major!L11:L16,TRUE,Major!N11:N16) -> 0 | C4: =SUMIF(Major!E3:E31,FALSE,Major!G3:G31)+SUMIF(Major!L3:L8,FALSE,Major!N3:N8)+SUMIF(Major!L11:L16,FALSE,Major!N11:N16) -> 0 | D4: =(B4/(C4+B4))*100 -> #DIV/0! | F4: =SUMIF(Minor!E3:E4,TRUE,Minor!G3:G4)+SUMIF(Minor!E7:E11,TRUE,Minor!G7:G11) -> 0 | G4: =SUMIF(Minor!E3:E4,FALSE,Minor!G3:G4)+SUMIF(Minor!E7:E11,FALSE,Minor!G7:G11) -> 0 | H4: =(F4/(F4+G4))*100 -> #DIV/0!
B7: Overall
B8: Total Credits Completed | C8: GPA | D8: Academic Level for Enrollment
B9: =B4+F4+SUM(#REF!)+SUM(Major!#REF!) -> #REF! | C9: ='GPA Calculations'!C3 -> #DIV/0! | D9: =VLOOKUP(Overview!B9,'GPA Calculations'!$I$5:'GPA Calculations'!$J$8,2) -> #REF!

Sheet Major
B2: Term | C2: Required Classes | D2: Name | E2: Complete? | F2: Grade | G2: Credits | I2: Term | J2: Elective | K2: Name | L2: Complete? | M2: Grade | N2: Credits
B3: 1 | C3: Course Number* | D3: Example | E3: TRUE | F3: {=_xlfn.IFS(B3=I$20,"IP",E3=FALSE,"")} -> IP | G3: 0 | L3: FALSE | M3: {=_xlfn.IFS(I3=I$20,"IP",L3=FALSE," ")}
E4: FALSE | F4: {=_xlfn.IFS(B4=I$20,"IP",E4=FALSE,"")} | L4: FALSE | M4: {=_xlfn.IFS(I4=I$20,"IP",L4=FALSE," ")} | S4: =M16
E5: FALSE | F5: {=_xlfn.IFS(B5=I$20,"IP",E5=FALSE,"")} | L5: FALSE | M5: {=_xlfn.IFS(I5=I$20,"IP",L5=FALSE," ")}
E6: FALSE | F6: {=_xlfn.IFS(B6=I$20,"IP",E6=FALSE,"")} | L6: FALSE | M6: {=_xlfn.IFS(I6=I$20,"IP",L6=FALSE," ")}
E7: FALSE | F7: {=_xlfn.IFS(B7=I$20,"IP",E7=FALSE,"")} | L7: FALSE | M7: {=_xlfn.IFS(I7=I$20,"IP",L7=FALSE," ")}
E8: FALSE | F8: {=_xlfn.IFS(B8=I$20,"IP",E8=FALSE,"")} | L8: FALSE | M8: {=_xlfn.IFS(I8=I$20,"IP",L8=FALSE," ")}
E9: FALSE | F9: {=_xlfn.IFS(B9=I$20,"IP",E9=FALSE,"")}
E10: FALSE | F10: {=_xlfn.IFS(B10=I$20,"IP",E10=FALSE,"")} | I10: Term | J10: General Education Elective | K10: Name | L10: Complete? | M10: Grade | N10: Credits
E11: FALSE | F11: {=_xlfn.IFS(B11=I$20,"IP",E11=FALSE,"")} | L11: FALSE | M11: {=_xlfn.IFS(I11=I$20,"IP",L11=FALSE,"")}
E12: FALSE | F12: {=_xlfn.IFS(B12=I$20,"IP",E12=FALSE,"")} | L12: FALSE | M12: {=_xlfn.IFS(I12=I$20,"IP",L12=FALSE,"")}
E13: FALSE | F13: {=_xlfn.IFS(B13=I$20,"IP",E13=FALSE,"")} | L13: FALSE | M13: {=_xlfn.IFS(I13=I$20,"IP",L13=FALSE,"")}
E14: FALSE | F14: {=_xlfn.IFS(B14=I$20,"IP",E14=FALSE,"")} | L14: FALSE | M14: {=_xlfn.IFS(I14=I$20,"IP",L14=FALSE,"")}
E15: FALSE | F15: {=_xlfn.IFS(B15=I$20,"IP",E15=FALSE,"")} | L15: FALSE | M15: {=_xlfn.IFS(I15=I$20,"IP",L15=FALSE,"")}
E16: FALSE | F16: {=_xlfn.IFS(B16=I$20,"IP",E16=FALSE,"")} | L16: FALSE | M16: {=_xlfn.IFS(I16=I$20,"IP",L16=FALSE,"")}
E17: FALSE | F17: {=_xlfn.IFS(B17=I$20,"IP",E17=FALSE,"")}
E18: FALSE | F18: {=_xlfn.IFS(B18=I$20,"IP",E18=FALSE,"")} | I18: Current Term | K18: Key
E19: FALSE | F19: {=_xlfn.IFS(B19=I$20,"IP",E19=FALSE,"")} | K19: IP = In Progress
E20: FALSE | F20: {=_xlfn.IFS(B20=I$20,"IP",E20=FALSE,"")} | I20: 1 | K20: N/A = Not Graded
E21: FALSE | F21: {=_xlfn.IFS(B21=I$20,"IP",E21=FALSE,"")}
E22: FALSE | F22: {=_xlfn.IFS(B22=I$20,"IP",E22=FALSE,"")}
E23: FALSE | F23: {=_xlfn.IFS(B23=I$20,"IP",E23=FALSE,"")}
E24: FALSE | F24: {=_xlfn.IFS(B24=I$20,"IP",E24=FALSE,"")}
E25: FALSE | F25: {=_xlfn.IFS(B25=I$20,"IP",E25=FALSE,"")}
E26: FALSE | F26: {=_xlfn.IFS(B26=I$20,"IP",E26=FALSE,"")}
E27: FALSE | F27: {=_xlfn.IFS(B27=I$20,"IP",E27=FALSE,"")}
E28: FALSE | F28: {=_xlfn.IFS(B28=I$20,"IP",E28=FALSE,"")}
E29: FALSE | F29: {=_xlfn.IFS(B29=I$20,"IP",E29=FALSE,"")}
E30: FALSE | F30: {=_xlfn.IFS(B30=I$20,"IP",E30=FALSE,"")}
E31: FALSE | F31: {=_xlfn.IFS(B31=I$20,"IP",E31=FALSE,"")}

Sheet Minor
B2: Term | C2: Required Classes | D2: Name | E2: Complete? | F2: Grade | G2: Credits
C3: Course Number* | E3: FALSE | F3: {=_xlfn.IFS(B3=Major!I$20,"IP",E3=FALSE,"")}
E4: FALSE | F4: {=_xlfn.IFS(B4=Major!I$20,"IP",E4=FALSE,"")}
B6: Term | C6: Elective | D6: Name | E6: Complete? | F6: Grade | G6: Credits
E7: FALSE | F7: {=_xlfn.IFS(B7=Major!I$20,"IP",E7=FALSE,"")}
E8: FALSE
E9: FALSE
E10: FALSE | F10: {=_xlfn.IFS(B10=Major!I$20,"IP",E10=FALSE,"")}
E11: FALSE | F11: {=_xlfn.IFS(B11=Major!I$20,"IP",E11=FALSE,"")}

Sheet GPA Calculations
B2: Total Completed Classes | C2: GPA
B3: =COUNTIF(E7:E52,FALSE) -> 0 | C3: =(SUMIF(E7:E52,FALSE,(G7:G52)))/(SUMIF(E7:E52,FALSE,(D7:D52))) -> #DIV/0! | I3: Enrollment classification reference
I4: Completed credit totals | J4: Academic level for enrollment
B5: Class Data | I5: 0 | J5: Freshman
B6: Completion Status | C6: Grade | D6: Credits | E6: Completed graded classes = False | F6: GPA Value | G6: Credit-Weighted GPA | I6: 24 | J6: Sophomore
B7: =Major!E3 -> TRUE | C7: =Major!F3 -> IP | D7: =Major!G3 -> 0 | E7: =OR(C7="N/A",C7="IP",C7=" ",B7=FALSE) -> TRUE | F7: =IF(E7=FALSE,(VLOOKUP(C7,I$12:J$24,2)),"N/A") -> N/A | G7: =F7*D7 -> #VALUE! | I7: 54 | J7: Junior
B8: =Major!E4 -> FALSE | C8: =Major!F4 | D8: =Major!G4 -> 0 | E8: =OR(C8="N/A",C8="IP",C8=" ",B8=FALSE) -> TRUE | F8: =IF(E8=FALSE,(VLOOKUP(C8,I$12:J$24,2)),"N/A") -> N/A | G8: =F8*D8 -> #VALUE! | I8: 84 | J8: Senior
B9: =Major!E5 -> FALSE | C9: =Major!F5 | D9: =Major!G5 -> 0 | E9: =OR(C9="N/A",C9="IP",C9=" ",B9=FALSE) -> TRUE | F9: =IF(E9=FALSE,(VLOOKUP(C9,I$12:J$24,2)),"N/A") -> N/A | G9: =F9*D9 -> #VALUE!
B10: =Major!E6 -> FALSE | C10: =Major!F6 | D10: =Major!G6 -> 0 | E10: =OR(C10="N/A",C10="IP",C10=" ",B10=FALSE) -> TRUE | F10: =IF(E10=FALSE,(VLOOKUP(C10,I$12:J$24,2)),"N/A") -> N/A | G10: =F10*D10 -> #VALUE!
B11: =Major!E7 -> FALSE | C11: =Major!F7 | D11: =Major!G7 -> 0 | E11: =OR(C11="N/A",C11="IP",C11=" ",B11=FALSE) -> TRUE | F11: =IF(E11=FALSE,(VLOOKUP(C11,I$12:J$24,2)),"N/A") -> N/A | G11: =F11*D11 -> #VALUE! | I11: GPA Reference
B12: =Major!E8 -> FALSE | C12: =Major!F8 | D12: =Major!G8 -> 0 | E12: =OR(C12="N/A",C12="IP",C12=" ",B12=FALSE) -> TRUE | F12: =IF(E12=FALSE,(VLOOKUP(C12,I$12:J$24,2)),"N/A") -> N/A | G12: =F12*D12 -> #VALUE! | I12: ="A" -> A | J12: 4
B13: =Major!E9 -> FALSE | C13: =Major!F9 | D13: =Major!G9 -> 0 | E13: =OR(C13="N/A",C13="IP",C13=" ",B13=FALSE) -> TRUE | F13: =IF(E13=FALSE,(VLOOKUP(C13,I$12:J$24,2)),"N/A") -> N/A | G13: =F13*D13 -> #VALUE! | I13: ="A-" -> A- | J13: 3.75
B14: =Major!E10 -> FALSE | C14: =Major!F10 | D14: =Major!G10 -> 0 | E14: =OR(C14="N/A",C14="IP",C14=" ",B14=FALSE) -> TRUE | F14: =IF(E14=FALSE,(VLOOKUP(C14,I$12:J$24,2)),"N/A") -> N/A | G14: =F14*D14 -> #VALUE! | I14: ="A+" -> A+ | J14: 4
B15: =Major!E11 -> FALSE | C15: =Major!F11 | D15: =Major!G11 -> 0 | E15: =OR(C15="N/A",C15="IP",C15=" ",B15=FALSE) -> TRUE | F15: =IF(E15=FALSE,(VLOOKUP(C15,I$12:J$24,2)),"N/A") -> N/A | G15: =F15*D15 -> #VALUE! | I15: ="B" -> B | J15: 3
B16: =Major!E12 -> FALSE | C16: =Major!F12 | D16: =Major!G12 -> 0 | E16: =OR(C16="N/A",C16="IP",C16=" ",B16=FALSE) -> TRUE | F16: =IF(E16=FALSE,(VLOOKUP(C16,I$12:J$24,2)),"N/A") -> N/A | G16: =F16*D16 -> #VALUE! | I16: ="B-" -> B- | J16: 2.75
B17: =Major!E13 -> FALSE | C17: =Major!F13 | D17: =Major!G13 -> 0 | E17: =OR(C17="N/A",C17="IP",C17=" ",B17=FALSE) -> TRUE | F17: =IF(E17=FALSE,(VLOOKUP(C17,I$12:J$24,2)),"N/A") -> N/A | G17: =F17*D17 -> #VALUE! | I17: ="B+" -> B+ | J17: 3.25
B18: =Major!E14 -> FALSE | C18: =Major!F14 | D18: =Major!G14 -> 0 | E18: =OR(C18="N/A",C18="IP",C18=" ",B18=FALSE) -> TRUE | F18: =IF(E18=FALSE,(VLOOKUP(C18,I$12:J$24,2)),"N/A") -> N/A | G18: =F18*D18 -> #VALUE! | I18: ="C" -> C | J18: 2
B19: =Major!E15 -> FALSE | C19: =Major!F15 | D19: =Major!G15 -> 0 | E19: =OR(C19="N/A",C19="IP",C19=" ",B19=FALSE) -> TRUE | F19: =IF(E19=FALSE,(VLOOKUP(C19,I$12:J$24,2)),"N/A") -> N/A | G19: =F19*D19 -> #VALUE! | I19: ="C-" -> C- | J19: 1.75
B20: =Major!E16 -> FALSE | C20: =Major!F16 | D20: =Major!G16 -> 0 | E20: =OR(C20="N/A",C20="IP",C20=" ",B20=FALSE) -> TRUE | F20: =IF(E20=FALSE,(VLOOKUP(C20,I$12:J$24,2)),"N/A") -> N/A | G20: =F20*D20 -> #VALUE! | I20: ="C+" -> C+ | J20: 2.25
B21: =Major!E17 -> FALSE | C21: =Major!F17 | D21: =Major!G17 -> 0 | E21: =OR(C21="N/A",C21="IP",C21=" ",B21=FALSE) -> TRUE | F21: =IF(E21=FALSE,(VLOOKUP(C21,I$12:J$24,2)),"N/A") -> N/A | G21: =F21*D21 -> #VALUE! | I21: ="D" -> D | J21: 1
B22: =Major!E18 -> FALSE | C22: =Major!F18 | D22: =Major!G18 -> 0 | E22: =OR(C22="N/A",C22="IP",C22=" ",B22=FALSE) -> TRUE | F22: =IF(E22=FALSE,(VLOOKUP(C22,I$12:J$24,2)),"N/A") -> N/A | G22: =F22*D22 -> #VALUE! | I22: ="D-" -> D- | J22: 0.75
B23: =Major!E19 -> FALSE | C23: =Major!F19 | D23: =Major!G19 -> 0 | E23: =OR(C23="N/A",C23="IP",C23=" ",B23=FALSE) -> TRUE | F23: =IF(E23=FALSE,(VLOOKUP(C23,I$12:J$24,2)),"N/A") -> N/A | G23: =F23*D23 -> #VALUE! | I23: ="D+" -> D+ | J23: 1.25
B24: =Major!E20 -> FALSE | C24: =Major!F20 | D24: =Major!G20 -> 0 | E24: =OR(C24="N/A",C24="IP",C24=" ",B24=FALSE) -> TRUE | F24: =IF(E24=FALSE,(VLOOKUP(C24,I$12:J$24,2)),"N/A") -> N/A | G24: =F24*D24 -> #VALUE! | I24: ="F" -> F | J24: 0
B25: =Major!E21 -> FALSE | C25: =Major!F21 | D25: =Major!G21 -> 0 | E25: =OR(C25="N/A",C25="IP",C25=" ",B25=FALSE) -> TRUE | F25: =IF(E25=FALSE,(VLOOKUP(C25,I$12:J$24,2)),"N/A") -> N/A | G25: =F25*D25 -> #VALUE!
B26: =Major!E22 -> FALSE | C26: =Major!F22 | D26: =Major!G22 -> 0 | E26: =OR(C26="N/A",C26="IP",C26=" ",B26=FALSE) -> TRUE | F26: =IF(E26=FALSE,(VLOOKUP(C26,I$12:J$24,2)),"N/A") -> N/A | G26: =F26*D26 -> #VALUE!
B27: =Major!E23 -> FALSE | C27: =Major!F23 | D27: =Major!G23 -> 0 | E27: =OR(C27="N/A",C27="IP",C27=" ",B27=FALSE) -> TRUE | F27: =IF(E27=FALSE,(VLOOKUP(C27,I$12:J$24,2)),"N/A") -> N/A | G27: =F27*D27 -> #VALUE!
B28: =Major!E24 -> FALSE | C28: =Major!F24 | D28: =Major!G24 -> 0 | E28: =OR(C28="N/A",C28="IP",C28=" ",B28=FALSE) -> TRUE | F28: =IF(E28=FALSE,(VLOOKUP(C28,I$12:J$24,2)),"N/A") -> N/A | G28: =F28*D28 -> #VALUE!
B29: =Major!E25 -> FALSE | C29: =Major!F25 | D29: =Major!G25 -> 0 | E29: =OR(C29="N/A",C29="IP",C29=" ",B29=FALSE) -> TRUE | F29: =IF(E29=FALSE,(VLOOKUP(C29,I$12:J$24,2)),"N/A") -> N/A | G29: =F29*D29 -> #VALUE!
B30: =Major!E26 -> FALSE | C30: =Major!F26 | D30: =Major!G26 -> 0 | E30: =OR(C30="N/A",C30="IP",C30=" ",B30=FALSE) -> TRUE | F30: =IF(E30=FALSE,(VLOOKUP(C30,I$12:J$24,2)),"N/A") -> N/A | G30: =F30*D30 -> #VALUE!
B31: =Major!E27 -> FALSE | C31: =Major!F27 | D31: =Major!G27 -> 0 | E31: =OR(C31="N/A",C31="IP",C31=" ",B31=FALSE) -> TRUE | F31: =IF(E31=FALSE,(VLOOKUP(C31,I$12:J$24,2)),"N/A") -> N/A | G31: =F31*D31 -> #VALUE!
B32: =Major!E28 -> FALSE | C32: =Major!F28 | D32: =Major!G28 -> 0 | E32: =OR(C32="N/A",C32="IP",C32=" ",B32=FALSE) -> TRUE | F32: =IF(E32=FALSE,(VLOOKUP(C32,I$12:J$24,2)),"N/A") -> N/A | G32: =F32*D32 -> #VALUE!
B33: =Major!E29 -> FALSE | C33: =Major!F29 | D33: =Major!G29 -> 0 | E33: =OR(C33="N/A",C33="IP",C33=" ",B33=FALSE) -> TRUE | F33: =IF(E33=FALSE,(VLOOKUP(C33,I$12:J$24,2)),"N/A") -> N/A | G33: =F33*D33 -> #VALUE!
B34: =Major!E30 -> FALSE | C34: =Major!F30 | D34: =Major!G30 -> 0 | E34: =OR(C34="N/A",C34="IP",C34=" ",B34=FALSE) -> TRUE | F34: =IF(E34=FALSE,(VLOOKUP(C34,I$12:J$24,2)),"N/A") -> N/A | G34: =F34*D34 -> #VALUE!
B35: =Major!E31 -> FALSE | C35: =Major!F31 | D35: =Major!G31 -> 0 | E35: =OR(C35="N/A",C35="IP",C35=" ",B35=FALSE) -> TRUE | F35: =IF(E35=FALSE,(VLOOKUP(C35,I$12:J$24,2)),"N/A") -> N/A | G35: =F35*D35 -> #VALUE!
B36: =Major!L3 -> FALSE | C36: =Major!M3 | D36: =Major!N3 -> 0 | E36: =OR(C36="N/A",C36="IP",C36=" ",B36=FALSE) -> TRUE | F36: =IF(E36=FALSE,(VLOOKUP(C36,I$12:J$24,2)),"N/A") -> N/A | G36: =F36*D36 -> #VALUE!
B37: =Major!L4 -> FALSE | C37: =Major!M4 | D37: =Major!N4 -> 0 | E37: =OR(C37="N/A",C37="IP",C37=" ",B37=FALSE) -> TRUE | F37: =IF(E37=FALSE,(VLOOKUP(C37,I$12:J$24,2)),"N/A") -> N/A | G37: =F37*D37 -> #VALUE!
B38: =Major!L5 -> FALSE | C38: =Major!M5 | D38: =Major!N5 -> 0 | E38: =OR(C38="N/A",C38="IP",C38=" ",B38=FALSE) -> TRUE | F38: =IF(E38=FALSE,(VLOOKUP(C38,I$12:J$24,2)),"N/A") -> N/A | G38: =F38*D38 -> #VALUE!
B39: =Major!L6 -> FALSE | C39: =Major!M6 | D39: =Major!N6 -> 0 | E39: =OR(C39="N/A",C39="IP",C39=" ",B39=FALSE) -> TRUE | F39: =IF(E39=FALSE,(VLOOKUP(C39,I$12:J$24,2)),"N/A") -> N/A | G39: =F39*D39 -> #VALUE!
B40: =Major!L7 -> FALSE | C40: =Major!M7 | D40: =Major!N7 -> 0 | E40: =OR(C40="N/A",C40="IP",C40=" ",B40=FALSE) -> TRUE | F40: =IF(E40=FALSE,(VLOOKUP(C40,I$12:J$24,2)),"N/A") -> N/A | G40: =F40*D40 -> #VALUE!
B41: =Major!L8 -> FALSE | C41: =Major!M8 | D41: =Major!N8 -> 0 | E41: =OR(C41="N/A",C41="IP",C41=" ",B41=FALSE) -> TRUE | F41: =IF(E41=FALSE,(VLOOKUP(C41,I$12:J$24,2)),"N/A") -> N/A | G41: =F41*D41 -> #VALUE!
...
